<?xml version="1.0"?>
<robot name="abb_irb_120_ejes12">
<!-- link list -->
  <link name="world"/>
  <link name="base_link">
    <inertial>
      <mass value="6.215"/>
      <origin rpy="0 0 0" xyz="-0.04204 8.01E-05 0.07964"/>
      <inertia ixx="0.0247272" ixy="-8.0784E-05" ixz="0.00130902" iyy="0.0491285" iyz="-8.0419E-06" izz="0.0472376"/>
    </inertial>
    <visual>
      <origin rpy="0 0 0" xyz="0 0 0"/>
      <geometry>
        <mesh filename="abb_irb_120/meshes/visual/base_link.stl"/>
      </geometry>
      <material name="">
        <color rgba="0.7372549 0.3490196 0.1607843 1"/>
      </material>
    </visual>
    <collision>
      <origin rpy="0 0 0" xyz="0 0 0"/>
      <geometry>
        <mesh filename="abb_irb_120/meshes/collision/base_link.stl"/>
      </geometry>
      <material name="">
        <color rgba="1 1 0 1"/>
      </material>
    </collision>
  </link>
  <link name="link_1">
    <inertial>
      <mass value="3.067"/>
      <origin rpy="0 0 0" xyz="9.77E-05 -0.00012 0.23841"/>
      <inertia ixx="0.0142175" ixy="-1.28579E-05" ixz="-2.31364E-05" iyy="0.0144041" iyz="1.93404E-05" izz="0.0104533"/>
    </inertial>
    <visual>
      <origin rpy="0 0 0" xyz="0 0 0"/>
      <geometry>
        <mesh filename="abb_irb_120/meshes/visual/link_1.stl"/>
      </geometry>
      <material name="">
        <color rgba="0.7372549 0.3490196 0.1607843 1"/>
      </material>
    </visual>
    <collision>
      <origin rpy="0 0 0" xyz="0 0 0"/>
      <geometry>
        <mesh filename="abb_irb_120/meshes/collision/link_1.stl"/>
      </geometry>
      <material name="">
        <color rgba="1 1 0 1"/>
      </material>
    </collision>
  </link>
  <link name="link_2">
    <inertial>
      <mass value="3.909"/>
      <origin rpy="0 0 0" xyz="0.00078 -0.00212 0.10124"/>
      <inertia ixx="0.0603111" ixy="9.83431E-06" ixz="5.72407E-05" iyy="0.041569" iyz="-0.00050497" izz="0.0259548"/>
    </inertial>
    <visual>
      <origin rpy="0 0 0" xyz="0 0 0"/>
      <geometry>
        <mesh filename="abb_irb_120/meshes/visual/link_2.stl"/>
      </geometry>
      <material name="">
        <color rgba="0.7372549 0.3490196 0.1607843 1"/>
      </material>
    </visual>
    <collision>
      <origin rpy="0 0 0" xyz="0 0 0"/>
      <geometry>
        <mesh filename="abb_irb_120/meshes/collision/link_2.stl"/>
      </geometry>
      <material name="">
        <color rgba="1 1 0 1"/>
      </material>
    </collision>
  </link>
 <link name="tool0"/>
  
<!-- end of link list -->

  <!-- joint list -->
  <joint name="fixed" type="fixed">
    <parent link="world"/>
    <child link="base_link"/>
  </joint>
  <joint name="joint_1" type="revolute">
    <origin rpy="0 0 0" xyz="0 0 0"/>
    <parent link="base_link"/>
    <child link="link_1"/>
    <limit effort="1000" lower="-2.87979" upper="2.87979" velocity="4.36332"/>
    <axis xyz="0 0 1"/>
    <dynamics damping="0.2" friction="10"/>
  </joint>
 <joint name="joint_2" type="revolute">
    <origin rpy="0 0 0" xyz="0 0 0.29"/>
    <parent link="link_1"/>
    <child link="link_2"/>
    <limit effort="1000" lower="-1.91986" upper="1.91986" velocity="4.36332"/>
    <axis xyz="0 1 0"/>
    <dynamics damping="0.2" friction="10"/>
  </joint>
 <joint name="joint2-tool0" type="fixed">
    <parent link="link_2"/>
    <child link="tool0"/>
    <origin rpy="0 0 0" xyz="0 0 0.27"/>
  </joint>
  <!-- end of joint list -->
  <transmission name="tran1">
    <type>transmission_interface/SimpleTransmission</type>
    <joint name="joint_1">
      <hardwareInterface>hardware_interface/EffortJointInterface</hardwareInterface>
    </joint>
    <actuator name="motor1">
      <mechanicalReduction>1</mechanicalReduction>
    </actuator>
  </transmission>
  <transmission name="tran2">
    <type>transmission_interface/SimpleTransmission</type>
    <joint name="joint_2">
      <hardwareInterface>hardware_interface/EffortJointInterface</hardwareInterface>
    </joint>
    <actuator name="motor2">
      <mechanicalReduction>1</mechanicalReduction>
    </actuator>
  </transmission>
 


  <gazebo reference="base_link">
    <material>Gazebo/Orange</material>
    <turnGravityOff>false</turnGravityOff>
  </gazebo>
  <gazebo reference="link_1">
    <material>Gazebo/Orange</material>
    <turnGravityOff>false</turnGravityOff>
  </gazebo>
  <gazebo reference="link_2">
    <material>Gazebo/Orange</material>
    <turnGravityOff>false</turnGravityOff>
  </gazebo>  

  <!-- end of transmision list -->





  <gazebo>
    <plugin name="gazebo_ros_control" filename="libgazebo_ros_control.so">
      <robotNamespace>/</robotNamespace>
    </plugin>
  </gazebo> 
</robot>
